Workbook

Sheet Fill in
A1: Pivot info sheet. One row per pivot; fill the cells you know and import it in Pivot Log (Fields > Import). Blank cells never erase what is already there.
A2: About the pivot (from the register) | M2: 1 Model needs | U2: 2 Checks, alerts, app | AL2: 3 Records & reporting | AX2: 4 Maintenance | BH2: Calculated
A3: System ID | B3: Farm | C3: Fields served | D3: 2026 crop(s) | E3: Planned acres | F3: Boundary acres | G3: On AgSense | H3: AgSense name | I3: AgSense gpm (typed in) | J3: 2027 pilot | K3: AgSense acres setting | L3: Order | M3: Irrigated acres (design or FSA) | N3: Design flow (gpm) | O3: Hours per rev at 100% | P3: Full or part circle (deg) | Q3: End gun (Y/N, model) | R3: Sprinkler package | S3: Water source | T3: Other pivots on same source | U3: Design pressure (psi) | V3: Wetted radius incl. end gun (ft) | W3: Length to last tower (ft) | X3: Towers (#) | Y3: Pivot make | Z3: Model | AA3: Control panel | AB3: Crop Link model | AC3: Flow meter | AD3: Pressure transducer | AE3: Rain gauge | AF3: Position sensing | AG3: Measured flow (gpm, date) | AH3: Dealer | AI3: Well / intake ID | AJ3: Power source | AK3: Drive type | AL3: FSA farm # (FSN) | AM3: FSA tract / CLU | AN3: GA EPD withdrawal permit # | AO3: State ag water meter ID | AP3: Power supplier / meter # | AQ3: Install year | AR3: Pivot serial / order # | AS3: Pump type | AT3: Pump/motor hp | AU3: Well depth / aquifer | AV3: EQIP / CSP history | AW3: Irrigated 2 of last 5 yrs | AX3: Sprinkler chart on file | AY3: Package install year | AZ3: Pressure regulators (psi) | BA3: End gun on-arc / booster | BB3: Corner arm / swing arm | BC3: VRI (speed / zone) | BD3: Measured pressure (psi, date) | BE3: Last uniformity test (date, CU %) | BF3: Known problems | BG3: Last service / repair | BH3: Tier 1 done | BI3: All done % | BJ3: In per rev at 100% (calc) | BK3: gpm per acre (calc) | BL3: Acres from radius (calc) | BM3: Check
A4: Where to get it | M4: Dealer / Office: Sprinkler chart (design acres) or FSA-578 | N4: Dealer / Field walk: Sprinkler chart, often taped inside the panel door | O4: Dealer / Field walk / AgSense web: Sprinkler chart, panel, or the AgSense unit settings | P4: Field walk: Crew: 360, or the degrees between the stops | Q4: Dealer / Field walk: Sprinkler chart or look at the last tower | R4: Dealer / Field walk: Sprinkler chart; or look: drops, on top, LEPA | S4: Office: Bo | T4: Office: Bo: list the pivots that share the well or pump | U4: Dealer / Field walk: Sprinkler chart | V4: Dealer: Sprinkler chart | W4: Dealer: Sprinkler chart | X4: Field walk: Count them | Y4: Field walk: Data plate at the pivot point | Z4: Field walk: Data plate | AA4: Field walk: Photo of the panel | AB4: Dealer / AgSense web: AgSense dealer, or the unit label | AC4: Field walk: Look on the pipe near the pivot point | AD4: Field walk / Dealer: Look at the pivot point | AE4: Field walk: Look on the pivot | AF4: Dealer: AgSense dealer | AG4: MIL test (winter): UGA Mobile Irrigation Lab or a flow meter | AH4: Office: Bo | AI4: Office: Bo: your name or number for the well or intake | AJ4: Office: Bo | AK4: Field walk: Panel or towers | AL4: Office: Prefilled from Field Master 2026; confirm | AM4: Office: FSA-578 or FSA maps | AN4: Office: EPD permit papers | AO4: Field walk: Tag on the state meter | AP4: Office: Power bill or fuel records | AQ4: Field walk / Dealer: Data plate or dealer | AR4: Field walk: Data plate | AS4: Field walk: Pump plate | AT4: Field walk: Motor plate | AU4: Office: Well log | AV4: Office: NRCS contracts | AW4: Office: Bo / FSA-578 | AX4: Office: Yes/No and where the photo lives | AY4: Office / Dealer: When nozzles were last replaced | AZ4: Dealer / Field walk: Sprinkler chart or regulator label | BA4: Field walk: Crew: sectors where it runs; booster pump yes/no | BB4: Field walk: Look | BC4: Dealer: Dealer | BD4: MIL test (winter): Mobile Irrigation Lab | BE4: MIL test (winter): Mobile Irrigation Lab | BF4: Field walk: Crew | BG4: Field walk: Crew / dealer

Sheet What matters
A1: Fields to collect, ranked by what the water model and app need
A2: Filled = pivots that already have it in the register. Rank 1 is the most important.
A4: Rank | B4: Tier | C4: Field | D4: Why it matters | E4: Best source | F4: Where to find it | G4: Filled now | H4: Still needed
A5: 1 | B5: 1 Model needs | C5: Irrigated acres (design or FSA) | D5: Divides gallons into inches. Field Master acres are the FSA field, often not the wetted circle. | E5: Dealer / Office | F5: Sprinkler chart (design acres) or FSA-578 | G5: 0 | H5: 81
A6: 2 | B6: 1 Model needs | C6: Design flow (gpm) | D6: Inches = gpm x hours / (452.6 x acres). Today only 22 pivots have a gpm, and it is typed into AgSense, not measured. | E6: Dealer / Field walk | F6: Sprinkler chart, often taped inside the panel door | G6: 0 | H6: 81
A7: 3 | B7: 1 Model needs | C7: Hours per rev at 100% | D7: Turns a % timer setting into depth. The app's watering instructions are given as a % timer. | E7: Dealer / Field walk / AgSense web | F7: Sprinkler chart, panel, or the AgSense unit settings | G7: 0 | H7: 81
A8: 4 | B8: 1 Model needs | C8: Full or part circle (deg) | D8: Part circles change acres and lap time. | E8: Field walk | F8: Crew: 360, or the degrees between the stops | G8: 0 | H8: 81
A9: 5 | B9: 1 Model needs | C9: End gun (Y/N, model) | D9: End gun adds acres and gpm while it is on. | E9: Dealer / Field walk | F9: Sprinkler chart or look at the last tower | G9: 0 | H9: 81
A10: 6 | B10: 1 Model needs | C10: Sprinkler package | D10: Sets application efficiency (LEPA about 95%, spray on drops about 85%, impacts on top about 75%). The model uses 85% for every pivot today. | E10: Dealer / Field walk | F10: Sprinkler chart; or look: drops, on top, LEPA | G10: 0 | H10: 81
A11: 7 | B11: 1 Model needs | C11: Water source | D11: Wells, ponds and creeks behave differently in drought and have different permits. | E11: Office | F11: Bo | G11: 0 | H11: 81
A12: 8 | B12: 1 Model needs | C12: Other pivots on same source | D12: Pivots on one well cannot all run at full flow. The app must not tell you to start both. | E12: Office | F12: Bo: list the pivots that share the well or pump | G12: 0 | H12: 81
A13: 9 | B13: 2 Checks, alerts, app | C13: Design pressure (psi) | D13: Baseline for low-pressure fault alerts. | E13: Dealer / Field walk | F13: Sprinkler chart | G13: 0 | H13: 81
A14: 10 | B14: 2 Checks, alerts, app | C14: Wetted radius incl. end gun (ft) | D14: Cross-checks acres: acres = 3.1416 x radius squared / 43,560. | E14: Dealer | F14: Sprinkler chart | G14: 0 | H14: 81
A15: 11 | B15: 2 Checks, alerts, app | C15: Length to last tower (ft) | D15: Cross-check for acres and the chart. | E15: Dealer | F15: Sprinkler chart | G15: 0 | H15: 81
A16: 12 | B16: 2 Checks, alerts, app | C16: Towers (#) | D16: Identifies the machine and the chart that goes with it. | E16: Field walk | F16: Count them | G16: 0 | H16: 81
... A51: 47 | B51: 4 Maintenance | C51: Last service / repair | D51: Date and what was done. | E51: Field walk | F51: Crew / dealer | G51: 0 | H51: 81

Sheet By source
A1: One trip per source: what to ask for or look at
A3: Dealer
A4: One email or call per dealer (Valley, Zimmatic, Reinke). Ask for the sprinkler chart (design printout) for each pivot, plus the AgSense unit details for the pivots on AgSense. A chart answers most of Tier 1 and 2 at once.
A5: Field | B5: Tier | C5: Where to find it
A6: Irrigated acres (design or FSA) | B6: 1 | C6: Sprinkler chart (design acres) or FSA-578
A7: Design flow (gpm) | B7: 1 | C7: Sprinkler chart, often taped inside the panel door
A8: Hours per rev at 100% | B8: 1 | C8: Sprinkler chart, panel, or the AgSense unit settings
A9: End gun (Y/N, model) | B9: 1 | C9: Sprinkler chart or look at the last tower
A10: Sprinkler package | B10: 1 | C10: Sprinkler chart; or look: drops, on top, LEPA
A11: Design pressure (psi) | B11: 2 | C11: Sprinkler chart
A12: Wetted radius incl. end gun (ft) | B12: 2 | C12: Sprinkler chart
A13: Length to last tower (ft) | B13: 2 | C13: Sprinkler chart
A14: Crop Link model | B14: 2 | C14: AgSense dealer, or the unit label
A15: Pressure transducer | B15: 2 | C15: Look at the pivot point
A16: Position sensing | B16: 2 | C16: AgSense dealer
A17: Install year | B17: 3 | C17: Data plate or dealer
... A20: VRI (speed / zone) | B20: 4 | C20: Dealer
A22: Field walk
A23: One stop per pivot, about 5 minutes. Take 5 photos: data plate at the pivot point, control panel (door open), sprinkler chart if it is in the panel, pump/motor plate, state water meter tag. Count towers, note the stops, end gun and any problems. Name photos '<pivot> - plate.jpg' etc. and upload them to the project; Claude reads them into this sheet.
A24: Field | B24: Tier | C24: Where to find it
A25: Design flow (gpm) | B25: 1 | C25: Sprinkler chart, often taped inside the panel door
A26: Hours per rev at 100% | B26: 1 | C26: Sprinkler chart, panel, or the AgSense unit settings
A27: Full or part circle (deg) | B27: 1 | C27: Crew: 360, or the degrees between the stops
A28: End gun (Y/N, model) | B28: 1 | C28: Sprinkler chart or look at the last tower
A29: Sprinkler package | B29: 1 | C29: Sprinkler chart; or look: drops, on top, LEPA
A30: Design pressure (psi) | B30: 2 | C30: Sprinkler chart
A31: Towers (#) | B31: 2 | C31: Count them
A32: Pivot make | B32: 2 | C32: Data plate at the pivot point
A33: Model | B33: 2 | C33: Data plate
A34: Control panel | B34: 2 | C34: Photo of the panel
A35: Flow meter | B35: 2 | C35: Look on the pipe near the pivot point
A36: Pressure transducer | B36: 2 | C36: Look at the pivot point
... A48: Last service / repair | B48: 4 | C48: Crew / dealer
A50: Office
A51: Things Bo knows or has on paper: wells and which pivots share them, power source and bills, FSA-578, EPD permits, EQIP history, dealer names.
A52: Field | B52: Tier | C52: Where to find it
A53: Irrigated acres (design or FSA) | B53: 1 | C53: Sprinkler chart (design acres) or FSA-578
A54: Water source | B54: 1 | C54: Bo
A55: Other pivots on same source | B55: 1 | C55: Bo: list the pivots that share the well or pump
A56: Dealer | B56: 2 | C56: Bo
...

Sheet Progress
A1: Progress (updates as the Fill in tab is filled)
A3: Field | B3: Tier | C3: Filled | D3: Of | E3: %
A4: Irrigated acres (design or FSA) | B4: 1 | C4: =COUNTA('Fill in'!M5:M85) | D4: 81 | E4: =C4/D4
A5: Design flow (gpm) | B5: 1 | C5: =COUNTA('Fill in'!N5:N85) | D5: 81 | E5: =C5/D5
A6: Hours per rev at 100% | B6: 1 | C6: =COUNTA('Fill in'!O5:O85) | D6: 81 | E6: =C6/D6
A7: Full or part circle (deg) | B7: 1 | C7: =COUNTA('Fill in'!P5:P85) | D7: 81 | E7: =C7/D7
A8: End gun (Y/N, model) | B8: 1 | C8: =COUNTA('Fill in'!Q5:Q85) | D8: 81 | E8: =C8/D8
A9: Sprinkler package | B9: 1 | C9: =COUNTA('Fill in'!R5:R85) | D9: 81 | E9: =C9/D9
A10: Water source | B10: 1 | C10: =COUNTA('Fill in'!S5:S85) | D10: 81 | E10: =C10/D10
A11: Other pivots on same source | B11: 1 | C11: =COUNTA('Fill in'!T5:T85) | D11: 81 | E11: =C11/D11
A12: Design pressure (psi) | B12: 2 | C12: =COUNTA('Fill in'!U5:U85) | D12: 81 | E12: =C12/D12
A13: Wetted radius incl. end gun (ft) | B13: 2 | C13: =COUNTA('Fill in'!V5:V85) | D13: 81 | E13: =C13/D13
A14: Length to last tower (ft) | B14: 2 | C14: =COUNTA('Fill in'!W5:W85) | D14: 81 | E14: =C14/D14
A15: Towers (#) | B15: 2 | C15: =COUNTA('Fill in'!X5:X85) | D15: 81 | E15: =C15/D15
A16: Pivot make | B16: 2 | C16: =COUNTA('Fill in'!Y5:Y85) | D16: 81 | E16: =C16/D16
A17: Model | B17: 2 | C17: =COUNTA('Fill in'!Z5:Z85) | D17: 81 | E17: =C17/D17
A18: Control panel | B18: 2 | C18: =COUNTA('Fill in'!AA5:AA85) | D18: 81 | E18: =C18/D18
A19: Crop Link model | B19: 2 | C19: =COUNTA('Fill in'!AB5:AB85) | D19: 81 | E19: =C19/D19
A20: Flow meter | B20: 2 | C20: =COUNTA('Fill in'!AC5:AC85) | D20: 81 | E20: =C20/D20
A21: Pressure transducer | B21: 2 | C21: =COUNTA('Fill in'!AD5:AD85) | D21: 81 | E21: =C21/D21
A22: Rain gauge | B22: 2 | C22: =COUNTA('Fill in'!AE5:AE85) | D22: 81 | E22: =C22/D22
A23: Position sensing | B23: 2 | C23: =COUNTA('Fill in'!AF5:AF85) | D23: 81 | E23: =C23/D23
A24: Measured flow (gpm, date) | B24: 2 | C24: =COUNTA('Fill in'!AG5:AG85) | D24: 81 | E24: =C24/D24
A25: Dealer | B25: 2 | C25: =COUNTA('Fill in'!AH5:AH85) | D25: 81 | E25: =C25/D25
A26: Well / intake ID | B26: 2 | C26: =COUNTA('Fill in'!AI5:AI85) | D26: 81 | E26: =C26/D26
A27: Power source | B27: 2 | C27: =COUNTA('Fill in'!AJ5:AJ85) | D27: 81 | E27: =C27/D27
A28: Drive type | B28: 2 | C28: =COUNTA('Fill in'!AK5:AK85) | D28: 81 | E28: =C28/D28
A29: FSA farm # (FSN) | B29: 3 | C29: =COUNTA('Fill in'!AL5:AL85) | D29: 81 | E29: =C29/D29
A30: FSA tract / CLU | B30: 3 | C30: =COUNTA('Fill in'!AM5:AM85) | D30: 81 | E30: =C30/D30
A31: GA EPD withdrawal permit # | B31: 3 | C31: =COUNTA('Fill in'!AN5:AN85) | D31: 81 | E31: =C31/D31
A32: State ag water meter ID | B32: 3 | C32: =COUNTA('Fill in'!AO5:AO85) | D32: 81 | E32: =C32/D32
A33: Power supplier / meter # | B33: 3 | C33: =COUNTA('Fill in'!AP5:AP85) | D33: 81 | E33: =C33/D33
A34: Install year | B34: 3 | C34: =COUNTA('Fill in'!AQ5:AQ85) | D34: 81 | E34: =C34/D34
A35: Pivot serial / order # | B35: 3 | C35: =COUNTA('Fill in'!AR5:AR85) | D35: 81 | E35: =C35/D35
A36: Pump type | B36: 3 | C36: =COUNTA('Fill in'!AS5:AS85) | D36: 81 | E36: =C36/D36
A37: Pump/motor hp | B37: 3 | C37: =COUNTA('Fill in'!AT5:AT85) | D37: 81 | E37: =C37/D37
A38: Well depth / aquifer | B38: 3 | C38: =COUNTA('Fill in'!AU5:AU85) | D38: 81 | E38: =C38/D38
A39: EQIP / CSP history | B39: 3 | C39: =COUNTA('Fill in'!AV5:AV85) | D39: 81 | E39: =C39/D39
A40: Irrigated 2 of last 5 yrs | B40: 3 | C40: =COUNTA('Fill in'!AW5:AW85) | D40: 81 | E40: =C40/D40
A41: Sprinkler chart on file | B41: 4 | C41: =COUNTA('Fill in'!AX5:AX85) | D41: 81 | E41: =C41/D41
...
